


/home/yjw5427/miniconda3/envs/trans/lib/python3.10/site-packages/peft/utils/other.py:611: UserWarning: Unable to fetch remote file due to the following error 403 Client Error. (Request ID: Root=1-67f3250d-27ee463d322326c83e91eeff;4fc41982-e4ca-478c-8a77-348fea0b2492)
Cannot access gated repo for url https://huggingface.co/meta-llama/Llama-3.2-3B/resolve/main/config.json.
Access to model meta-llama/Llama-3.2-3B is restricted and you are not in the authorized list. Visit https://huggingface.co/meta-llama/Llama-3.2-3B to ask for access. - silently ignoring the lookup for the file config.json in meta-llama/Llama-3.2-3B.
  warnings.warn(
/home/yjw5427/miniconda3/envs/trans/lib/python3.10/site-packages/peft/utils/save_and_load.py:195: UserWarning: Could not find a config file in meta-llama/Llama-3.2-3B - will assume that the vocabulary was not modified.
  warnings.warn(
{'train_runtime': 14.7247, 'train_samples_per_second': 1.63, 'train_steps_per_second': 0.204, 'train_loss': 3.562255859375, 'epoch': 1.0}
***** train metrics *****
  epoch                    =        1.0
  total_flos               =   393776GF
  train_loss               =     3.5623
  train_runtime            = 0:00:14.72
  train_samples            =         50
  train_samples_per_second =       1.63
  train_steps_per_second   =      0.204
3
1.2e-06


 67%|███████████████████████████████████████████████████████████████████▎                                 | 2/3 [00:04<00:02,  2.47s/it]
{'train_runtime': 7.4185, 'train_samples_per_second': 3.235, 'train_steps_per_second': 0.404, 'train_loss': 3.0633138020833335, 'epoch': 1.0}
***** train metrics *****
  epoch                    =        1.0
  total_flos               =   393776GF
  train_loss               =     3.0633
  train_runtime            = 0:00:07.41
  train_samples            =         50
  train_samples_per_second =      3.235
  train_steps_per_second   =      0.404
3
/home/yjw5427/miniconda3/envs/trans/lib/python3.10/site-packages/peft/utils/other.py:611: UserWarning: Unable to fetch remote file due to the following error 403 Client Error. (Request ID: Root=1-67f32515-04efb2d14c26db8f50151eae;b74e7a0f-22b1-4954-a25f-01542a509328)
Cannot access gated repo for url https://huggingface.co/meta-llama/Llama-3.2-3B/resolve/main/config.json.
Access to model meta-llama/Llama-3.2-3B is restricted and you are not in the authorized list. Visit https://huggingface.co/meta-llama/Llama-3.2-3B to ask for access. - silently ignoring the lookup for the file config.json in meta-llama/Llama-3.2-3B.
  warnings.warn(
/home/yjw5427/miniconda3/envs/trans/lib/python3.10/site-packages/peft/utils/save_and_load.py:195: UserWarning: Could not find a config file in meta-llama/Llama-3.2-3B - will assume that the vocabulary was not modified.
  warnings.warn(


 67%|███████████████████████████████████████████████████████████████████▎                                 | 2/3 [00:04<00:02,  2.47s/it]
{'train_runtime': 7.4347, 'train_samples_per_second': 3.228, 'train_steps_per_second': 0.404, 'train_loss': 3.04119873046875, 'epoch': 1.0}
***** train metrics *****
  epoch                    =        1.0
  total_flos               =   393776GF
  train_loss               =     3.0412
  train_runtime            = 0:00:07.43
  train_samples            =         50
  train_samples_per_second =      3.228
  train_steps_per_second   =      0.404
3
/home/yjw5427/miniconda3/envs/trans/lib/python3.10/site-packages/peft/utils/other.py:611: UserWarning: Unable to fetch remote file due to the following error 403 Client Error. (Request ID: Root=1-67f3251e-0357065418089cab48fbe71e;65e12b70-d552-48f1-801e-a3ed4e73bcf8)
Cannot access gated repo for url https://huggingface.co/meta-llama/Llama-3.2-3B/resolve/main/config.json.
Access to model meta-llama/Llama-3.2-3B is restricted and you are not in the authorized list. Visit https://huggingface.co/meta-llama/Llama-3.2-3B to ask for access. - silently ignoring the lookup for the file config.json in meta-llama/Llama-3.2-3B.
  warnings.warn(
/home/yjw5427/miniconda3/envs/trans/lib/python3.10/site-packages/peft/utils/save_and_load.py:195: UserWarning: Could not find a config file in meta-llama/Llama-3.2-3B - will assume that the vocabulary was not modified.
  warnings.warn(


/home/yjw5427/miniconda3/envs/trans/lib/python3.10/site-packages/peft/utils/other.py:611: UserWarning: Unable to fetch remote file due to the following error 403 Client Error. (Request ID: Root=1-67f32526-172a5e84248e96056c2caace;cd4c9600-a9c1-43a6-9973-a6f31b926026)
Cannot access gated repo for url https://huggingface.co/meta-llama/Llama-3.2-3B/resolve/main/config.json.
Access to model meta-llama/Llama-3.2-3B is restricted and you are not in the authorized list. Visit https://huggingface.co/meta-llama/Llama-3.2-3B to ask for access. - silently ignoring the lookup for the file config.json in meta-llama/Llama-3.2-3B.
  warnings.warn(
/home/yjw5427/miniconda3/envs/trans/lib/python3.10/site-packages/peft/utils/save_and_load.py:195: UserWarning: Could not find a config file in meta-llama/Llama-3.2-3B - will assume that the vocabulary was not modified.
  warnings.warn(
{'train_runtime': 7.4315, 'train_samples_per_second': 3.229, 'train_steps_per_second': 0.404, 'train_loss': 4.0439453125, 'epoch': 1.0}
***** train metrics *****
  epoch                    =        1.0
  total_flos               =   393776GF
  train_loss               =     4.0439
  train_runtime            = 0:00:07.43
  train_samples            =         50
  train_samples_per_second =      3.229
  train_steps_per_second   =      0.404
3
1.2e-06


 67%|███████████████████████████████████████████████████████████████████▎                                 | 2/3 [00:04<00:02,  2.47s/it]
{'train_runtime': 7.4324, 'train_samples_per_second': 3.229, 'train_steps_per_second': 0.404, 'train_loss': 3.6666259765625, 'epoch': 1.0}
***** train metrics *****
  epoch                    =        1.0
  total_flos               =   393776GF
  train_loss               =     3.6666
  train_runtime            = 0:00:07.43
  train_samples            =         50
  train_samples_per_second =      3.229
/home/yjw5427/miniconda3/envs/trans/lib/python3.10/site-packages/peft/utils/other.py:611: UserWarning: Unable to fetch remote file due to the following error 403 Client Error. (Request ID: Root=1-67f3252f-36ea12d46f1167447c6c811f;07188f3b-4c80-48ef-bfeb-bfbd3ad010c8)
Cannot access gated repo for url https://huggingface.co/meta-llama/Llama-3.2-3B/resolve/main/config.json.
Access to model meta-llama/Llama-3.2-3B is restricted and you are not in the authorized list. Visit https://huggingface.co/meta-llama/Llama-3.2-3B to ask for access. - silently ignoring the lookup for the file config.json in meta-llama/Llama-3.2-3B.
  warnings.warn(
/home/yjw5427/miniconda3/envs/trans/lib/python3.10/site-packages/peft/utils/save_and_load.py:195: UserWarning: Could not find a config file in meta-llama/Llama-3.2-3B - will assume that the vocabulary was not modified.
  warnings.warn(




 87%|█████████████████████████████████████████████████████████████████████████████████████▊             | 13/15 [00:08<00:01,  1.40it/s]
***** eval metrics *****
  epoch                   =        1.0
  eval_accuracy           =     0.2672
  eval_loss               =     3.5183
  eval_runtime            = 0:00:10.42
  eval_samples            =        116
  eval_samples_per_second =     11.132
  eval_steps_per_second   =       1.44
Traceback (most recent call last):██████████████████████████████████████████████████████████████████████| 15/15 [00:09<00:00,  1.65it/s]
  File "/data/home/yjw5427/translora/fed_lora_cls.py", line 860, in <module>
    main()
  File "/data/home/yjw5427/translora/fed_lora_cls.py", line 824, in main
    with open(outfolder + file_name, 'wb') as f:
FileNotFoundError: [Errno 2] No such file or directory: '/home/yjw5427/translora/results/lora_llama32_3b_TimSchopf/medical_abstracts_fedavg_rounds[20]_llr[3e-06]_li[1.0]_iid[iid]_nuser[10]_suser[5]_lora.pkl'
Traceback (most recent call last):
  File "/data/home/yjw5427/translora/fed_lora_cls.py", line 860, in <module>
    main()
  File "/data/home/yjw5427/translora/fed_lora_cls.py", line 824, in main
    with open(outfolder + file_name, 'wb') as f:
FileNotFoundError: [Errno 2] No such file or directory: '/home/yjw5427/translora/results/lora_llama32_3b_TimSchopf/medical_abstracts_fedavg_rounds[20]_llr[3e-06]_li[1.0]_iid[iid]_nuser[10]_suser[5]_lora.pkl'